Workbook

Sheet ChamDiem
A1: BẢNG CHẤM ĐIỂM CẦU THỦ — CHIA 2 ĐỘI SÂN 7 (3 người chấm: Tuyên / Mạnh / Nam)
A2: Mỗi cầu thủ có 3 dòng (Tuyên / Mạnh / Nam). Bấm ô → SỔ XUỐNG chọn. Vị trí / Chân / Mức độ chỉ điền 1 LẦN ở DÒNG ĐẦU (Tuyên). Chấm SO VỚI MẶT BẰNG CỦA HỘI; khâu nào không rõ để 5–6; TM = 0 nếu không bắt gôn.
A3: Ý NGHĨA 9 TIÊU CHÍ
A4: KT = Kỹ thuật · CH = Chuyền · DĐ = Dứt điểm · PN = Phòng ngự · TC = Tốc độ
A5: TL = Thể lực (sức bền/mạnh) · ĐN = Độ nhiệt (chịu chạy, máu lửa) · TD = Tư duy · TM = Thủ môn (0 nếu không bắt gôn)
A6: THANG ĐIỂM (chấm so với mặt bằng của hội)
A7: 1–2 Rất yếu · 3–4 Dưới trung bình · 5–6 Trung bình (để mức này nếu không rõ) · 7–8 Khá tốt · 9–10 Xuất sắc
A8: VỊ TRÍ (6 vai): GK Thủ môn · Thòng (trung vệ giữa) · HV Hậu vệ biên · TVtt Tiền vệ trung tâm · TV Tiền vệ cánh · TĐ Tiền đạo. 'Vị trí chính' = sở trường; 'Đá được thêm' = vai trò khác chơi được.
A10: STT | B10: Tên cầu thủ | C10: Người chấm | D10: Vị trí chính | E10: Đá được thêm | F10: Chân thuận | G10: Mức độ hay đi đá | H10: Kỹ thuật (KT) | I10: Chuyền (CH) | J10: Dứt điểm (DĐ) | K10: Phòng ngự (PN) | L10: Tốc độ (TC) | M10: Thể lực (TL) | N10: Độ nhiệt (ĐN) | O10: Tư duy (TD) | P10: Thủ môn (TM·0-10) | Q10: Ghi chú
A11: 1 | B11: Cris Dao | C11: Tuyên | D11: HV | E11: Thòng/TVtt/TV | H11: 6 | I11: 6 | J11: 5 | K11: 6 | L11: 8 | M11: 6 | N11: 3 | O11: 6 | P11: 0 | Q11: Tuyên: Trung bình, nhanh, lười
C12: Mạnh
C13: Nam
A14: 2 | B14: Doan Ha | C14: Tuyên | D14: TĐ | H14: 7 | I14: 5 | J14: 7 | K14: 4 | L14: 4 | M14: 7 | N14: 8 | O14: 6 | P14: 0 | Q14: Tuyên: Trung bình, chậm, chịu chạy
C15: Mạnh
C16: Nam
A17: 3 | B17: Duy Hùng | C17: Tuyên | D17: Thòng | E17: HV/TVtt/TV | H17: 4 | I17: 5 | J17: 3 | K17: 5 | L17: 3 | M17: 5 | N17: 5 | O17: 5 | P17: 0 | Q17: Tuyên: Yếu, chậm
C18: Mạnh
C19: Nam
A20: 4 | B20: Hoàng Duy | C20: Tuyên | D20: HV | E20: Thòng/TVtt/TV | H20: 7 | I20: 8 | J20: 6 | K20: 8 | L20: 8 | M20: 8 | N20: 8 | O20: 8 | P20: 0 | Q20: Tuyên: Khá, nhanh, chịu chạy
C21: Mạnh
C22: Nam
A23: 5 | B23: Hoàng Thiên | C23: Tuyên | D23: TĐ | H23: 10 | I23: 8 | J23: 10 | K23: 7 | L23: 9 | M23: 9 | N23: 9 | O23: 9 | P23: 8 | Q23: Tuyên: Ngôi sao, nhanh, chịu chạy
C24: Mạnh
C25: Nam
A26: 6 | B26: Hưng | C26: Tuyên | D26: Thòng | E26: HV/TVtt/TV | H26: 7 | I26: 8 | J26: 6 | K26: 8 | L26: 4 | M26: 8 | N26: 8 | O26: 8 | P26: 0 | Q26: Tuyên: Khá, chậm, chịu chạy
C27: Mạnh
C28: Nam
A29: 7 | B29: Huy Hoàng | C29: Tuyên | D29: TVtt | E29: Thòng/HV/TV/TĐ | H29: 9 | I29: 9 | J29: 8 | K29: 9 | L29: 9 | M29: 9 | N29: 9 | O29: 9 | P29: 0 | Q29: Tuyên: Ngôi sao, nhanh, chịu chạy
C30: Mạnh
C31: Nam
A32: 8 | B32: Mạnh Khắc | C32: Tuyên | D32: Thòng | E32: HV/TVtt/TV/TĐ | H32: 6 | I32: 6 | J32: 5 | K32: 6 | L32: 4 | M32: 6 | N32: 3 | O32: 6 | P32: 0 | Q32: Tuyên: Trung bình, chậm, lười
C33: Mạnh
C34: Nam
A35: 9 | B35: Mạnh Tiến | C35: Tuyên | D35: HV | E35: Thòng | H35: 5 | I35: 6 | J35: 4 | K35: 7 | L35: 8 | M35: 6 | N35: 8 | O35: 6 | P35: 5 | Q35: Tuyên: Trung bình, nhanh, chịu chạy
C36: Mạnh
C37: Nam
A38: 10 | B38: Nam Khắc | C38: Tuyên | D38: HV | E38: Thòng | H38: 7 | I38: 7 | J38: 6 | K38: 9 | L38: 8 | M38: 8 | N38: 8 | O38: 8 | P38: 0 | Q38: Tuyên: Khá, nhanh, chịu chạy
C39: Mạnh
C40: Nam
A41: 11 | B41: Nguyễn Danh Tuyên | C41: Tuyên | D41: HV | E41: Thòng/TVtt/TV | H41: 7 | I41: 8 | J41: 6 | K41: 8 | L41: 8 | M41: 8 | N41: 8 | O41: 8 | P41: 0 | Q41: Tuyên: Khá, nhanh, chịu chạy
...

Sheet TongHop
A1: TỔNG HỢP — ĐIỂM TRUNG BÌNH 3 NGƯỜI CHẤM (Tuyên/Mạnh/Nam) — tự động từ tab 'ChamDiem'
A3: STT | B3: Tên cầu thủ | C3: Vị trí chính | D3: KT | E3: CH | F3: DĐ | G3: PN | H3: TC | I3: TL | J3: ĐN | K3: TD | L3: TM | M3: Overall (TB 8 mục)
A4: 1 | B4: Cris Dao | C4: =IF(ChamDiem!D11="","",ChamDiem!D11) | D4: =IFERROR(ROUND(AVERAGE(ChamDiem!H11:H13),1),"") | E4: =IFERROR(ROUND(AVERAGE(ChamDiem!I11:I13),1),"") | F4: =IFERROR(ROUND(AVERAGE(ChamDiem!J11:J13),1),"") | G4: =IFERROR(ROUND(AVERAGE(ChamDiem!K11:K13),1),"") | H4: =IFERROR(ROUND(AVERAGE(ChamDiem!L11:L13),1),"") | I4: =IFERROR(ROUND(AVERAGE(ChamDiem!M11:M13),1),"") | J4: =IFERROR(ROUND(AVERAGE(ChamDiem!N11:N13),1),"") | K4: =IFERROR(ROUND(AVERAGE(ChamDiem!O11:O13),1),"") | L4: =IFERROR(ROUND(AVERAGE(ChamDiem!P11:P13),1),"") | M4: =IFERROR(ROUND(AVERAGE(D4:K4),1),"")
A5: 2 | B5: Doan Ha | C5: =IF(ChamDiem!D14="","",ChamDiem!D14) | D5: =IFERROR(ROUND(AVERAGE(ChamDiem!H14:H16),1),"") | E5: =IFERROR(ROUND(AVERAGE(ChamDiem!I14:I16),1),"") | F5: =IFERROR(ROUND(AVERAGE(ChamDiem!J14:J16),1),"") | G5: =IFERROR(ROUND(AVERAGE(ChamDiem!K14:K16),1),"") | H5: =IFERROR(ROUND(AVERAGE(ChamDiem!L14:L16),1),"") | I5: =IFERROR(ROUND(AVERAGE(ChamDiem!M14:M16),1),"") | J5: =IFERROR(ROUND(AVERAGE(ChamDiem!N14:N16),1),"") | K5: =IFERROR(ROUND(AVERAGE(ChamDiem!O14:O16),1),"") | L5: =IFERROR(ROUND(AVERAGE(ChamDiem!P14:P16),1),"") | M5: =IFERROR(ROUND(AVERAGE(D5:K5),1),"")
A6: 3 | B6: Duy Hùng | C6: =IF(ChamDiem!D17="","",ChamDiem!D17) | D6: =IFERROR(ROUND(AVERAGE(ChamDiem!H17:H19),1),"") | E6: =IFERROR(ROUND(AVERAGE(ChamDiem!I17:I19),1),"") | F6: =IFERROR(ROUND(AVERAGE(ChamDiem!J17:J19),1),"") | G6: =IFERROR(ROUND(AVERAGE(ChamDiem!K17:K19),1),"") | H6: =IFERROR(ROUND(AVERAGE(ChamDiem!L17:L19),1),"") | I6: =IFERROR(ROUND(AVERAGE(ChamDiem!M17:M19),1),"") | J6: =IFERROR(ROUND(AVERAGE(ChamDiem!N17:N19),1),"") | K6: =IFERROR(ROUND(AVERAGE(ChamDiem!O17:O19),1),"") | L6: =IFERROR(ROUND(AVERAGE(ChamDiem!P17:P19),1),"") | M6: =IFERROR(ROUND(AVERAGE(D6:K6),1),"")
A7: 4 | B7: Hoàng Duy | C7: =IF(ChamDiem!D20="","",ChamDiem!D20) | D7: =IFERROR(ROUND(AVERAGE(ChamDiem!H20:H22),1),"") | E7: =IFERROR(ROUND(AVERAGE(ChamDiem!I20:I22),1),"") | F7: =IFERROR(ROUND(AVERAGE(ChamDiem!J20:J22),1),"") | G7: =IFERROR(ROUND(AVERAGE(ChamDiem!K20:K22),1),"") | H7: =IFERROR(ROUND(AVERAGE(ChamDiem!L20:L22),1),"") | I7: =IFERROR(ROUND(AVERAGE(ChamDiem!M20:M22),1),"") | J7: =IFERROR(ROUND(AVERAGE(ChamDiem!N20:N22),1),"") | K7: =IFERROR(ROUND(AVERAGE(ChamDiem!O20:O22),1),"") | L7: =IFERROR(ROUND(AVERAGE(ChamDiem!P20:P22),1),"") | M7: =IFERROR(ROUND(AVERAGE(D7:K7),1),"")
A8: 5 | B8: Hoàng Thiên | C8: =IF(ChamDiem!D23="","",ChamDiem!D23) | D8: =IFERROR(ROUND(AVERAGE(ChamDiem!H23:H25),1),"") | E8: =IFERROR(ROUND(AVERAGE(ChamDiem!I23:I25),1),"") | F8: =IFERROR(ROUND(AVERAGE(ChamDiem!J23:J25),1),"") | G8: =IFERROR(ROUND(AVERAGE(ChamDiem!K23:K25),1),"") | H8: =IFERROR(ROUND(AVERAGE(ChamDiem!L23:L25),1),"") | I8: =IFERROR(ROUND(AVERAGE(ChamDiem!M23:M25),1),"") | J8: =IFERROR(ROUND(AVERAGE(ChamDiem!N23:N25),1),"") | K8: =IFERROR(ROUND(AVERAGE(ChamDiem!O23:O25),1),"") | L8: =IFERROR(ROUND(AVERAGE(ChamDiem!P23:P25),1),"") | M8: =IFERROR(ROUND(AVERAGE(D8:K8),1),"")
A9: 6 | B9: Hưng | C9: =IF(ChamDiem!D26="","",ChamDiem!D26) | D9: =IFERROR(ROUND(AVERAGE(ChamDiem!H26:H28),1),"") | E9: =IFERROR(ROUND(AVERAGE(ChamDiem!I26:I28),1),"") | F9: =IFERROR(ROUND(AVERAGE(ChamDiem!J26:J28),1),"") | G9: =IFERROR(ROUND(AVERAGE(ChamDiem!K26:K28),1),"") | H9: =IFERROR(ROUND(AVERAGE(ChamDiem!L26:L28),1),"") | I9: =IFERROR(ROUND(AVERAGE(ChamDiem!M26:M28),1),"") | J9: =IFERROR(ROUND(AVERAGE(ChamDiem!N26:N28),1),"") | K9: =IFERROR(ROUND(AVERAGE(ChamDiem!O26:O28),1),"") | L9: =IFERROR(ROUND(AVERAGE(ChamDiem!P26:P28),1),"") | M9: =IFERROR(ROUND(AVERAGE(D9:K9),1),"")
A10: 7 | B10: Huy Hoàng | C10: =IF(ChamDiem!D29="","",ChamDiem!D29) | D10: =IFERROR(ROUND(AVERAGE(ChamDiem!H29:H31),1),"") | E10: =IFERROR(ROUND(AVERAGE(ChamDiem!I29:I31),1),"") | F10: =IFERROR(ROUND(AVERAGE(ChamDiem!J29:J31),1),"") | G10: =IFERROR(ROUND(AVERAGE(ChamDiem!K29:K31),1),"") | H10: =IFERROR(ROUND(AVERAGE(ChamDiem!L29:L31),1),"") | I10: =IFERROR(ROUND(AVERAGE(ChamDiem!M29:M31),1),"") | J10: =IFERROR(ROUND(AVERAGE(ChamDiem!N29:N31),1),"") | K10: =IFERROR(ROUND(AVERAGE(ChamDiem!O29:O31),1),"") | L10: =IFERROR(ROUND(AVERAGE(ChamDiem!P29:P31),1),"") | M10: =IFERROR(ROUND(AVERAGE(D10:K10),1),"")
A11: 8 | B11: Mạnh Khắc | C11: =IF(ChamDiem!D32="","",ChamDiem!D32) | D11: =IFERROR(ROUND(AVERAGE(ChamDiem!H32:H34),1),"") | E11: =IFERROR(ROUND(AVERAGE(ChamDiem!I32:I34),1),"") | F11: =IFERROR(ROUND(AVERAGE(ChamDiem!J32:J34),1),"") | G11: =IFERROR(ROUND(AVERAGE(ChamDiem!K32:K34),1),"") | H11: =IFERROR(ROUND(AVERAGE(ChamDiem!L32:L34),1),"") | I11: =IFERROR(ROUND(AVERAGE(ChamDiem!M32:M34),1),"") | J11: =IFERROR(ROUND(AVERAGE(ChamDiem!N32:N34),1),"") | K11: =IFERROR(ROUND(AVERAGE(ChamDiem!O32:O34),1),"") | L11: =IFERROR(ROUND(AVERAGE(ChamDiem!P32:P34),1),"") | M11: =IFERROR(ROUND(AVERAGE(D11:K11),1),"")
A12: 9 | B12: Mạnh Tiến | C12: =IF(ChamDiem!D35="","",ChamDiem!D35) | D12: =IFERROR(ROUND(AVERAGE(ChamDiem!H35:H37),1),"") | E12: =IFERROR(ROUND(AVERAGE(ChamDiem!I35:I37),1),"") | F12: =IFERROR(ROUND(AVERAGE(ChamDiem!J35:J37),1),"") | G12: =IFERROR(ROUND(AVERAGE(ChamDiem!K35:K37),1),"") | H12: =IFERROR(ROUND(AVERAGE(ChamDiem!L35:L37),1),"") | I12: =IFERROR(ROUND(AVERAGE(ChamDiem!M35:M37),1),"") | J12: =IFERROR(ROUND(AVERAGE(ChamDiem!N35:N37),1),"") | K12: =IFERROR(ROUND(AVERAGE(ChamDiem!O35:O37),1),"") | L12: =IFERROR(ROUND(AVERAGE(ChamDiem!P35:P37),1),"") | M12: =IFERROR(ROUND(AVERAGE(D12:K12),1),"")
A13: 10 | B13: Nam Khắc | C13: =IF(ChamDiem!D38="","",ChamDiem!D38) | D13: =IFERROR(ROUND(AVERAGE(ChamDiem!H38:H40),1),"") | E13: =IFERROR(ROUND(AVERAGE(ChamDiem!I38:I40),1),"") | F13: =IFERROR(ROUND(AVERAGE(ChamDiem!J38:J40),1),"") | G13: =IFERROR(ROUND(AVERAGE(ChamDiem!K38:K40),1),"") | H13: =IFERROR(ROUND(AVERAGE(ChamDiem!L38:L40),1),"") | I13: =IFERROR(ROUND(AVERAGE(ChamDiem!M38:M40),1),"") | J13: =IFERROR(ROUND(AVERAGE(ChamDiem!N38:N40),1),"") | K13: =IFERROR(ROUND(AVERAGE(ChamDiem!O38:O40),1),"") | L13: =IFERROR(ROUND(AVERAGE(ChamDiem!P38:P40),1),"") | M13: =IFERROR(ROUND(AVERAGE(D13:K13),1),"")
A14: 11 | B14: Nguyễn Danh Tuyên | C14: =IF(ChamDiem!D41="","",ChamDiem!D41) | D14: =IFERROR(ROUND(AVERAGE(ChamDiem!H41:H43),1),"") | E14: =IFERROR(ROUND(AVERAGE(ChamDiem!I41:I43),1),"") | F14: =IFERROR(ROUND(AVERAGE(ChamDiem!J41:J43),1),"") | G14: =IFERROR(ROUND(AVERAGE(ChamDiem!K41:K43),1),"") | H14: =IFERROR(ROUND(AVERAGE(ChamDiem!L41:L43),1),"") | I14: =IFERROR(ROUND(AVERAGE(ChamDiem!M41:M43),1),"") | J14: =IFERROR(ROUND(AVERAGE(ChamDiem!N41:N43),1),"") | K14: =IFERROR(ROUND(AVERAGE(ChamDiem!O41:O43),1),"") | L14: =IFERROR(ROUND(AVERAGE(ChamDiem!P41:P43),1),"") | M14: =IFERROR(ROUND(AVERAGE(D14:K14),1),"")
A15: 12 | B15: Nguyễn Khắc Trọng | C15: =IF(ChamDiem!D44="","",ChamDiem!D44) | D15: =IFERROR(ROUND(AVERAGE(ChamDiem!H44:H46),1),"") | E15: =IFERROR(ROUND(AVERAGE(ChamDiem!I44:I46),1),"") | F15: =IFERROR(ROUND(AVERAGE(ChamDiem!J44:J46),1),"") | G15: =IFERROR(ROUND(AVERAGE(ChamDiem!K44:K46),1),"") | H15: =IFERROR(ROUND(AVERAGE(ChamDiem!L44:L46),1),"") | I15: =IFERROR(ROUND(AVERAGE(ChamDiem!M44:M46),1),"") | J15: =IFERROR(ROUND(AVERAGE(ChamDiem!N44:N46),1),"") | K15: =IFERROR(ROUND(AVERAGE(ChamDiem!O44:O46),1),"") | L15: =IFERROR(ROUND(AVERAGE(ChamDiem!P44:P46),1),"") | M15: =IFERROR(ROUND(AVERAGE(D15:K15),1),"")
A16: 13 | B16: Nguyen Quy Bong | C16: =IF(ChamDiem!D47="","",ChamDiem!D47) | D16: =IFERROR(ROUND(AVERAGE(ChamDiem!H47:H49),1),"") | E16: =IFERROR(ROUND(AVERAGE(ChamDiem!I47:I49),1),"") | F16: =IFERROR(ROUND(AVERAGE(ChamDiem!J47:J49),1),"") | G16: =IFERROR(ROUND(AVERAGE(ChamDiem!K47:K49),1),"") | H16: =IFERROR(ROUND(AVERAGE(ChamDiem!L47:L49),1),"") | I16: =IFERROR(ROUND(AVERAGE(ChamDiem!M47:M49),1),"") | J16: =IFERROR(ROUND(AVERAGE(ChamDiem!N47:N49),1),"") | K16: =IFERROR(ROUND(AVERAGE(ChamDiem!O47:O49),1),"") | L16: =IFERROR(ROUND(AVERAGE(ChamDiem!P47:P49),1),"") | M16: =IFERROR(ROUND(AVERAGE(D16:K16),1),"")
A17: 14 | B17: Nguyễn Văn Quyền | C17: =IF(ChamDiem!D50="","",ChamDiem!D50) | D17: =IFERROR(ROUND(AVERAGE(ChamDiem!H50:H52),1),"") | E17: =IFERROR(ROUND(AVERAGE(ChamDiem!I50:I52),1),"") | F17: =IFERROR(ROUND(AVERAGE(ChamDiem!J50:J52),1),"") | G17: =IFERROR(ROUND(AVERAGE(ChamDiem!K50:K52),1),"") | H17: =IFERROR(ROUND(AVERAGE(ChamDiem!L50:L52),1),"") | I17: =IFERROR(ROUND(AVERAGE(ChamDiem!M50:M52),1),"") | J17: =IFERROR(ROUND(AVERAGE(ChamDiem!N50:N52),1),"") | K17: =IFERROR(ROUND(AVERAGE(ChamDiem!O50:O52),1),"") | L17: =IFERROR(ROUND(AVERAGE(ChamDiem!P50:P52),1),"") | M17: =IFERROR(ROUND(AVERAGE(D17:K17),1),"")
A18: 15 | B18: Quang Minh | C18: =IF(ChamDiem!D53="","",ChamDiem!D53) | D18: =IFERROR(ROUND(AVERAGE(ChamDiem!H53:H55),1),"") | E18: =IFERROR(ROUND(AVERAGE(ChamDiem!I53:I55),1),"") | F18: =IFERROR(ROUND(AVERAGE(ChamDiem!J53:J55),1),"") | G18: =IFERROR(ROUND(AVERAGE(ChamDiem!K53:K55),1),"") | H18: =IFERROR(ROUND(AVERAGE(ChamDiem!L53:L55),1),"") | I18: =IFERROR(ROUND(AVERAGE(ChamDiem!M53:M55),1),"") | J18: =IFERROR(ROUND(AVERAGE(ChamDiem!N53:N55),1),"") | K18: =IFERROR(ROUND(AVERAGE(ChamDiem!O53:O55),1),"") | L18: =IFERROR(ROUND(AVERAGE(ChamDiem!P53:P55),1),"") | M18: =IFERROR(ROUND(AVERAGE(D18:K18),1),"")
A19: 16 | B19: Quý Tàu | C19: =IF(ChamDiem!D56="","",ChamDiem!D56) | D19: =IFERROR(ROUND(AVERAGE(ChamDiem!H56:H58),1),"") | E19: =IFERROR(ROUND(AVERAGE(ChamDiem!I56:I58),1),"") | F19: =IFERROR(ROUND(AVERAGE(ChamDiem!J56:J58),1),"") | G19: =IFERROR(ROUND(AVERAGE(ChamDiem!K56:K58),1),"") | H19: =IFERROR(ROUND(AVERAGE(ChamDiem!L56:L58),1),"") | I19: =IFERROR(ROUND(AVERAGE(ChamDiem!M56:M58),1),"") | J19: =IFERROR(ROUND(AVERAGE(ChamDiem!N56:N58),1),"") | K19: =IFERROR(ROUND(AVERAGE(ChamDiem!O56:O58),1),"") | L19: =IFERROR(ROUND(AVERAGE(ChamDiem!P56:P58),1),"") | M19: =IFERROR(ROUND(AVERAGE(D19:K19),1),"")
A20: 17 | B20: Quyết Nguyễn | C20: =IF(ChamDiem!D59="","",ChamDiem!D59) | D20: =IFERROR(ROUND(AVERAGE(ChamDiem!H59:H61),1),"") | E20: =IFERROR(ROUND(AVERAGE(ChamDiem!I59:I61),1),"") | F20: =IFERROR(ROUND(AVERAGE(ChamDiem!J59:J61),1),"") | G20: =IFERROR(ROUND(AVERAGE(ChamDiem!K59:K61),1),"") | H20: =IFERROR(ROUND(AVERAGE(ChamDiem!L59:L61),1),"") | I20: =IFERROR(ROUND(AVERAGE(ChamDiem!M59:M61),1),"") | J20: =IFERROR(ROUND(AVERAGE(ChamDiem!N59:N61),1),"") | K20: =IFERROR(ROUND(AVERAGE(ChamDiem!O59:O61),1),"") | L20: =IFERROR(ROUND(AVERAGE(ChamDiem!P59:P61),1),"") | M20: =IFERROR(ROUND(AVERAGE(D20:K20),1),"")
A21: 18 | B21: Trịnh Mạnh | C21: =IF(ChamDiem!D62="","",ChamDiem!D62) | D21: =IFERROR(ROUND(AVERAGE(ChamDiem!H62:H64),1),"") | E21: =IFERROR(ROUND(AVERAGE(ChamDiem!I62:I64),1),"") | F21: =IFERROR(ROUND(AVERAGE(ChamDiem!J62:J64),1),"") | G21: =IFERROR(ROUND(AVERAGE(ChamDiem!K62:K64),1),"") | H21: =IFERROR(ROUND(AVERAGE(ChamDiem!L62:L64),1),"") | I21: =IFERROR(ROUND(AVERAGE(ChamDiem!M62:M64),1),"") | J21: =IFERROR(ROUND(AVERAGE(ChamDiem!N62:N64),1),"") | K21: =IFERROR(ROUND(AVERAGE(ChamDiem!O62:O64),1),"") | L21: =IFERROR(ROUND(AVERAGE(ChamDiem!P62:P64),1),"") | M21: =IFERROR(ROUND(AVERAGE(D21:K21),1),"")
A22: 19 | B22: Trịnh Tuấn Anh | C22: =IF(ChamDiem!D65="","",ChamDiem!D65) | D22: =IFERROR(ROUND(AVERAGE(ChamDiem!H65:H67),1),"") | E22: =IFERROR(ROUND(AVERAGE(ChamDiem!I65:I67),1),"") | F22: =IFERROR(ROUND(AVERAGE(ChamDiem!J65:J67),1),"") | G22: =IFERROR(ROUND(AVERAGE(ChamDiem!K65:K67),1),"") | H22: =IFERROR(ROUND(AVERAGE(ChamDiem!L65:L67),1),"") | I22: =IFERROR(ROUND(AVERAGE(ChamDiem!M65:M67),1),"") | J22: =IFERROR(ROUND(AVERAGE(ChamDiem!N65:N67),1),"") | K22: =IFERROR(ROUND(AVERAGE(ChamDiem!O65:O67),1),"") | L22: =IFERROR(ROUND(AVERAGE(ChamDiem!P65:P67),1),"") | M22: =IFERROR(ROUND(AVERAGE(D22:K22),1),"")
A23: 20 | B23: Văn Thanh | C23: =IF(ChamDiem!D68="","",ChamDiem!D68) | D23: =IFERROR(ROUND(AVERAGE(ChamDiem!H68:H70),1),"") | E23: =IFERROR(ROUND(AVERAGE(ChamDiem!I68:I70),1),"") | F23: =IFERROR(ROUND(AVERAGE(ChamDiem!J68:J70),1),"") | G23: =IFERROR(ROUND(AVERAGE(ChamDiem!K68:K70),1),"") | H23: =IFERROR(ROUND(AVERAGE(ChamDiem!L68:L70),1),"") | I23: =IFERROR(ROUND(AVERAGE(ChamDiem!M68:M70),1),"") | J23: =IFERROR(ROUND(AVERAGE(ChamDiem!N68:N70),1),"") | K23: =IFERROR(ROUND(AVERAGE(ChamDiem!O68:O70),1),"") | L23: =IFERROR(ROUND(AVERAGE(ChamDiem!P68:P70),1),"") | M23: =IFERROR(ROUND(AVERAGE(D23:K23),1),"")
